<?xml version="1.0" encoding="utf-8"?>
<!-- This URDF was automatically created by SolidWorks to URDF Exporter! Originally created by Stephen Brawner (brawner@gmail.com) 
     Commit Version: 1.6.0-4-g7f85cfe  Build Version: 1.6.7995.38578
     For more information, please see http://wiki.ros.org/sw_urdf_exporter -->
<robot
  name="urdf_with_tutorial">
  <link
    name="Link_1">
    <inertial>
      <origin
        xyz="0 0.0075 7.5102E-19"
        rpy="0 0 0" />
      <mass
        value="0.16493" />
      <inertia
        ixx="0.00010618"
        ixy="-1.1952E-37"
        ixz="0"
        iyy="0.00020617"
        iyz="-5.5662E-38"
        izz="0.00010618" />
    </inertial>
    <visual>
      <origin
        xyz="0 0 0"
        rpy="0 0 0" />
      <geometry>
        <mesh
          filename="package://urdf_with_tutorial/meshes/Link_1.STL" />
      </geometry>
      <material
        name="">
        <color
          rgba="0.75294 0.75294 0.75294 1" />
      </material>
    </visual>
    <collision>
      <origin
        xyz="0 0 0"
        rpy="0 0 0" />
      <geometry>
        <mesh
          filename="package://urdf_with_tutorial/meshes/Link_1.STL" />
      </geometry>
    </collision>
  </link>
  <link
    name="Link_2">
    <inertial>
      <origin
        xyz="1.7683E-17 0.016837 -0.0015755"
        rpy="0 0 0" />
      <mass
        value="0.047388" />
      <inertia
        ixx="4.2395E-05"
        ixy="-2.0852E-21"
        ixz="2.5477E-21"
        iyy="3.4858E-05"
        iyz="1.7294E-06"
        izz="1.694E-05" />
    </inertial>
    <visual>
      <origin
        xyz="0 0 0"
        rpy="0 0 0" />
      <geometry>
        <mesh
          filename="package://urdf_with_tutorial/meshes/Link_2.STL" />
      </geometry>
      <material
        name="">
        <color
          rgba="0.75294 0.75294 0.75294 1" />
      </material>
    </visual>
    <collision>
      <origin
        xyz="0 0 0"
        rpy="0 0 0" />
      <geometry>
        <mesh
          filename="package://urdf_with_tutorial/meshes/Link_2.STL" />
      </geometry>
    </collision>
  </link>
  <joint
    name="Joint_1"
    type="continuous">
    <origin
      xyz="0 0.015 0"
      rpy="0 -0.0042717 0" />
    <parent
      link="Link_1" />
    <child
      link="Link_2" />
    <axis
      xyz="0 1 0" />
  </joint>
  <link
    name="Link_3">
    <inertial>
      <origin
        xyz="0.0010298 0.045148 0.0042493"
        rpy="0 0 0" />
      <mass
        value="0.16163" />
      <inertia
        ixx="0.00023466"
        ixy="5.7388E-06"
        ixz="-5.4065E-08"
        iyy="7.2095E-05"
        iyz="3.0225E-05"
        izz="0.00019733" />
    </inertial>
    <visual>
      <origin
        xyz="0 0 0"
        rpy="0 0 0" />
      <geometry>
        <mesh
          filename="package://urdf_with_tutorial/meshes/Link_3.STL" />
      </geometry>
      <material
        name="">
        <color
          rgba="0.75294 0.75294 0.75294 1" />
      </material>
    </visual>
    <collision>
      <origin
        xyz="0 0 0"
        rpy="0 0 0" />
      <geometry>
        <mesh
          filename="package://urdf_with_tutorial/meshes/Link_3.STL" />
      </geometry>
    </collision>
  </link>
  <joint
    name="Joint_2"
    type="continuous">
    <origin
      xyz="0 0.04 0"
      rpy="0 0 0.0020432" />
    <parent
      link="Link_2" />
    <child
      link="Link_3" />
    <axis
      xyz="0 0 1" />
  </joint>
  <link
    name="Link_4">
    <inertial>
      <origin
        xyz="0.074623 -0.00061109 0.0049493"
        rpy="0 0 0" />
      <mass
        value="0.25627" />
      <inertia
        ixx="9.6663E-05"
        ixy="-9.987E-06"
        ixz="6.0669E-05"
        iyy="0.00059082"
        iyz="-4.686E-08"
        izz="0.00054819" />
    </inertial>
    <visual>
      <origin
        xyz="0 0 0"
        rpy="0 0 0" />
      <geometry>
        <mesh
          filename="package://urdf_with_tutorial/meshes/Link_4.STL" />
      </geometry>
      <material
        name="">
        <color
          rgba="0.75294 0.75294 0.75294 1" />
      </material>
    </visual>
    <collision>
      <origin
        xyz="0 0 0"
        rpy="0 0 0" />
      <geometry>
        <mesh
          filename="package://urdf_with_tutorial/meshes/Link_4.STL" />
      </geometry>
    </collision>
  </link>
  <joint
    name="Joint_3"
    type="continuous">
    <origin
      xyz="-0.0015069 0.10426 -9.3709E-05"
      rpy="0 0 -0.018221" />
    <parent
      link="Link_3" />
    <child
      link="Link_4" />
    <axis
      xyz="0 0 1" />
  </joint>
</robot>